Workbook

Sheet 2024
A1: # | B1: Valor Bruto | C1: Descuento | D1: Nombre de cliente/proveedor | E1: Subtotal | F1: Impuesto | G1: ReteFuente | H1: Rete IVA | I1: Rete ICA | J1: Total Reteciones | K1: Total Documento | L1: Cod SN | M1: NIT | N1: City | O1: Vendedor en doc | P1: Vendedor Actual | Q1: Canal de Cliente | R1: PARTICIPACION CLIENTE
A2: 1247 | B2: 2.3925762e+09 | C2: 89357047 | D2: M SIERRA FERRETEROS S.A.S. "MONTEVIDEO" | E2: 2.3032191e+09 | F2: 4.3761164e+08 | G2: 55624645 | H2: 0 | I2: 0 | J2: 55624645 | K2: 2.6852061e+09 | L2: 90134981300 | M2: 901349813-9 | N2: BOGOTA - BOGOTA | O2: GRANDES CUENTAS | P2: GRANDES CUENTAS | Q2: MAYORISTA INDUSTRIAL | R2: =E2/$E$2034 -> 0.045879949
A3: 307 | B3: 1.9321613e+09 | C3: 464046.78 | D3: CENTRO PINTUCOLOR S.A.S. | E3: 1.9316973e+09 | F3: 3.6702249e+08 | G3: 44148359 | H3: 0 | I3: 0 | J3: 44148359 | K3: 2.2545714e+09 | L3: 90058246400 | M3: 900582464-5 | N3: BARRANCABERMEJA - SANTANDER | O3: EVELIO GARCIA - SANTANDER | P3: EVELIO GARCIA - SANTANDER | Q3: GRAN DISTRIBUIDOR | R3: =E3/$E$2034 -> 0.038479263
A4: 1273 | B4: 1153020562 | C4: 14940866 | D4: MARTILLO DISTRIBUIDOR MAYORISTA S.A.S. | E4: 1.1380797e+09 | F4: 2.1623514e+08 | G4: 26494247 | H4: 0 | I4: 0 | J4: 26494247 | K4: 1.3278206e+09 | L4: 90144410400 | M4: 901444104-1 | N4: CALI - VALLE DEL CAUCA | O4: JORGE CASTRO - VALLE DE CAUCA | P4: JORGE CASTRO - VALLE DE CAUCA | Q4: MAYORISTA INDUSTRIAL | R4: =E4/$E$2034 -> 0.022670461
A5: 1292 | B5: 1062240262 | C5: 2349974.6 | D5: MATERIALES SU CONSTRUCCION S.A. | E5: 1.0598903e+09 | F5: 2.0137915e+08 | G5: 22679976 | H5: 0 | I5: 0 | J5: 22679976 | K5: 1.2385895e+09 | L5: 80014765000 | M5: 800147650-1 | N5: MEDELLIN - ANTIOQUIA | O5: ANTIOQUIA | P5: ANTIOQUIA | Q5: MAYORISTA INDUSTRIAL | R5: =E5/$E$2034 -> 0.021112934
A6: 609 | B6: 986195843 | C6: 2914125.9 | D6: FEDUSE S.A.S | E6: 9.8328172e+08 | F6: 1.8682353e+08 | G6: 22838255 | H6: 0 | I6: 0 | J6: 22838255 | K6: 1.147267e+09 | L6: 89130321200 | M6: 891303212-9 | N6: GUADALAJARA DE BUGA - VALLE DE | O6: JORGE CASTRO - VALLE DE CAUCA | P6: JORGE CASTRO - VALLE DE CAUCA | Q6: GRAN DISTRIBUIDOR | R6: =E6/$E$2034 -> 0.019586897
A7: 736 | B7: 954636523 | C7: 4799038.1 | D7: FERRETERIA TUBOLAMINAS S A-CALI | E7: 9.4983748e+08 | F7: 1.8046912e+08 | G7: 22337185 | H7: 25645302 | I7: 0 | J7: 47982487 | K7: 1.0823241e+09 | L7: 89032442001 | M7: 890324420-0 | N7: CALI - VALLE DEL CAUCA | O7: JORGE CASTRO - VALLE DE CAUCA | P7: JORGE CASTRO - VALLE DE CAUCA | Q7: GRAN DISTRIBUIDOR | R7: =E7/$E$2034 -> 0.01892069
A8: 1051 | B8: 929659150 | C8: 8664023.3 | D8: INDURRUEDAS S A S "BMANGA" | E8: 9.2099513e+08 | F8: 1.7498907e+08 | G8: 19642262 | H8: 0 | I8: 0 | J8: 19642262 | K8: 1.0763419e+09 | L8: 89020795600 | M8: 890207956-5 | N8: BUCARAMANGA - SANTANDER | O8: EVELIO GARCIA - SANTANDER | P8: EVELIO GARCIA - SANTANDER | Q8: MAYORISTA INDUSTRIAL | R8: =E8/$E$2034 -> 0.018346153
A9: 1023 | B9: 759311128 | C9: 933426.82 | D9: HOLCIM COLOMBIA S.A | E9: 7.583777e+08 | F9: 1.4409176e+08 | G9: 17812192 | H9: 20305899 | I9: 0 | J9: 38118091 | K9: 8.6435137e+08 | L9: 86000980800 | M9: 860009808-5 | N9: BOGOTA - BOGOTA | O9: GRANDES CUENTAS | P9: GRANDES CUENTAS | Q9: MAYORISTA INDUSTRIAL | R9: =E9/$E$2034 -> 0.015106826
A10: 1246 | B10: 6.5493795e+08 | C10: 22842515 | D10: M SIERRA FERRETEROS S.A.S "TIENDA BLER CENTRO" | E10: 6.3209543e+08 | F10: 1.2009813e+08 | G10: 15602633 | H10: 0 | I10: 0 | J10: 15602633 | K10: 736590933 | L10: 90134981301 | M10: 901349813-9 | N10: BOGOTA - BOGOTA | O10: GRANDES CUENTAS | P10: GRANDES CUENTAS | Q10: MAYORISTA INDUSTRIAL | R10: =E10/$E$2034 -> 0.012591293
A11: 385 | B11: 552274178 | C11: 1871664.2 | D11: CONSTRULAR S.A.S. | E11: 5.5040251e+08 | F11: 0 | G11: 11500856 | H11: 0 | I11: 0 | J11: 11500856 | K11: 5.3890166e+08 | L11: 90046116100 | M11: 900461161-1 | N11: LETICIA - AMAZONAS | O11: INSTITUCIONAL | P11: INSTITUCIONAL | Q11: GRAN DISTRIBUIDOR | R11: =E11/$E$2034 -> 0.010963976
A12: 1841 | B12: 502582007 | C12: 461122.2 | D12: SIDOC S.A.S. "YUMBO" | E12: 5.0212088e+08 | F12: 95402968 | G12: 11277482 | H12: 8128134.3 | I12: 0 | J12: 19405616 | K12: 5.7811824e+08 | L12: 89033302300 | M12: 890333023-8 | N12: YUMBO - VALLE DEL CAUCA | O12: JORGE CASTRO - VALLE DE CAUCA | P12: JORGE CASTRO - VALLE DE CAUCA | Q12: GRAN DISTRIBUIDOR | R12: =E12/$E$2034 -> 0.01000221
A13: 1700 | B13: 5.1770995e+08 | C13: 44609328 | D13: ROBAYO RAUL/DISTRIBUCIONES ROBAYO | E13: 4.7310062e+08 | F13: 89889118 | G13: 0 | H13: 0 | I13: 0 | J13: 0 | K13: 5.6298974e+08 | L13: 7954332100 | M13: 79294188-4 | N13: BOGOTA - BOGOTA | O13: GRANDES CUENTAS | P13: GRANDES CUENTAS | Q13: MAYORISTA INDUSTRIAL | R13: =E13/$E$2034 -> 0.0094241282
... A1060: 370 | B1060: 3852777 | C1060: 0 | D1060: CONSORCIO ALTO RENDIMIENTO IF | E1060: 3852777 | F1060: 712077.63 | G1060: 43849.12 | H1060: 0 | I1060: 0 | J1060: 43849.12 | K1060: 4521005.5 | L1060: 90167456600 | M1060: 901674566-7 | N1060: BOGOTA - BOGOTA | O1060: INSTITUCIONAL | P1060: INSTITUCIONAL | Q1060: INDUSTRIAL 2 | R1060: =E1060/$E$2034 -> 7.6747024e-05
A1061: 1309 | B1061: 3846874 | C1061: 0 | D1061: METAL CARGO SAS | E1061: 3846874 | F1061: 730906.06 | G1061: 80516 | H1061: 0 | I1061: 0 | J1061: 80516 | K1061: 4497264.1 | L1061: 90029319400 | M1061: 900293194-1 | O1061: INDUSTRIAL | P1061: INDUSTRIAL | Q1061: PVP | R1061: =E1061/$E$2034 -> 7.6629436e-05
A1062: 1948 | B1062: 3841040 | C1062: 0 | D1062: TU CASITA DE PINTURAS S EN C | E1062: 3841040 | F1062: 729797.6 | G1062: 96026 | H1062: 0 | I1062: 0 | J1062: 96026 | K1062: 4474811.6 | L1062: 90088842200 | M1062: 900888422-0 | N1062: GIRARDOT - CUNDINAMARCA | O1062: OMAR MONTAÑA -SUR TOLIMA | P1062: OMAR MONTAÑA -SUR TOLIMA | Q1062: DISTRIBUIDOR | R1062: =E1062/$E$2034 -> 7.6513223e-05
A1063: 1302 | B1063: 3836962 | C1063: 0 | D1063: MELO MUETE ALBA MERCEDES/LEO PINTURAS | E1063: 3836962 | F1063: 729022.78 | G1063: 0 | H1063: 0 | I1063: 0 | J1063: 0 | K1063: 4565984.8 | L1063: 3975698300 | M1063: 39756983-1 | N1063: BOGOTA - BOGOTA | O1063: DIANA ARENAS - LOCALIDAD FONTIBON | P1063: DIANA ARENAS - LOCALIDAD FONTIBON | Q1063: DISTRIBUIDOR | R1063: =E1063/$E$2034 -> 7.643199e-05
A1064: 806 | B1064: 3836270 | C1064: 0 | D1064: G Y J FERRETERIAS S.A. - BARRANQUILLA | E1064: 3836270 | F1064: 728891.3 | G1064: 79132.75 | H1064: 109333.7 | I1064: 0 | J1064: 188466.45 | K1064: 4376694.8 | L1064: 80013042608 | M1064: 800130426-3 | N1064: BARRANQUILLA - ATLANTICO | O1064: CRISTIAN BETANCOURT - COSTA ATLANTICA CENTRO | P1064: CRISTIAN BETANCOURT - COSTA ATLANTICA CENTRO | Q1064: GRAN DISTRIBUIDOR | R1064: =E1064/$E$2034 -> 7.6418205e-05
A1065: 379 | B1065: 3831228 | C1065: 0 | D1065: CONSTRUDISEÑOS INGENIERIA S.A.S | E1065: 3831228 | F1065: 727933.32 | G1065: 95780.7 | H1065: 0 | I1065: 0 | J1065: 95780.7 | K1065: 4463380.6 | L1065: 90104049400 | M1065: 901040494-4 | N1065: TURBACO - BOLIVAR | O1065: CRISTIAN BETANCOURT - COSTA ATLANTICA CENTRO | P1065: CRISTIAN BETANCOURT - COSTA ATLANTICA CENTRO | Q1065: DISTRIBUIDOR | R1065: =E1065/$E$2034 -> 7.6317769e-05
A1066: 1180 | B1066: 3828332 | C1066: 0 | D1066: LA PERLA DEL COLOR S.A.S. | E1066: 3828332 | F1066: 727383.08 | G1066: 82553.15 | H1066: 0 | I1066: 0 | J1066: 82553.15 | K1066: 4473161.9 | L1066: 90111827700 | M1066: 901118277-1 | N1066: BOGOTA - BOGOTA | O1066: ALFONSO ALBA - LOCALIDAD USAQUEN | P1066: ALFONSO ALBA - LOCALIDAD USAQUEN | Q1066: DISTRIBUIDOR | R1066: =E1066/$E$2034 -> 7.6260081e-05
A1067: 1385 | B1067: 3825636 | C1067: 0 | D1067: MUNDIAL DE DOBLECES S.A.S "PRINCIPAL" | E1067: 3825636 | F1067: 726870.84 | G1067: 34770.52 | H1067: 0 | I1067: 0 | J1067: 34770.52 | K1067: 4517736.3 | L1067: 83008067500 | M1067: 830080675-4 | N1067: BOGOTA - BOGOTA | O1067: ALEJANDRO CARANTON -LOCALIDAD KENNEDY | P1067: ALEJANDRO CARANTON -LOCALIDAD KENNEDY | Q1067: DISTRIBUIDOR | R1067: =E1067/$E$2034 -> 7.6206377e-05
A1068: 1449 | B1068: 3811544 | C1068: 0 | D1068: ORDOÑEZ MENESES LUZ ELIANY / UNIACABADOS QUILICHAO | E1068: 3811544 | F1068: 724193.36 | G1068: 0 | H1068: 0 | I1068: 0 | J1068: 0 | K1068: 4535737.4 | L1068: 114407078000 | M1068: 1144070780-1 | N1068: SANTANDER DE QUILICHAO - CAUCA | O1068: JORGE CASTRO - CAUCA | P1068: JORGE CASTRO - CAUCA | Q1068: DISTRIBUIDOR | R1068: =E1068/$E$2034 -> 7.5925665e-05
A1069: 697 | B1069: 3809224 | C1069: 0 | D1069: FERRETERIA LOS FIERROS S.A.S "CDS BELLO" | E1069: 3809224 | F1069: 723752.56 | G1069: 41391.95 | H1069: 0 | I1069: 0 | J1069: 41391.95 | K1069: 4491584.6 | L1069: 81101242714 | M1069: 811012427-5 | N1069: BELLO - ANTIOQUIA | O1069: ANTIOQUIA | P1069: ANTIOQUIA | Q1069: GRAN DISTRIBUIDOR | R1069: =E1069/$E$2034 -> 7.5879451e-05
A1070: 1707 | B1070: 3788559 | C1070: 8542.35 | D1070: RODRIGUEZ BERNAL ORLANDO | E1070: 3780016.6 | F1070: 718203.16 | G1070: 0 | H1070: 0 | I1070: 0 | J1070: 0 | K1070: 4498219.8 | L1070: 7920538200 | M1070: 79205382-7 | N1070: SOACHA - CUNDINAMARCA | O1070: ALEJANDRO CARANTON -SOACHA - SIBATE | P1070: ALEJANDRO CARANTON -SOACHA - SIBATE | Q1070: DISTRIBUIDOR | R1070: =E1070/$E$2034 -> 7.5297643e-05
A1071: 1589 | B1071: 3786444 | C1071: 25057.08 | D1071: PINZON CARDENAS JAIME ERNESTO / PINTAPINTOR | E1071: 3761386.9 | F1071: 714663.51 | G1071: 0 | H1071: 0 | I1071: 0 | J1071: 0 | K1071: 4476050.4 | L1071: 1018478826 | M1071: 1018478826 | N1071: BOGOTA - BOGOTA | O1071: ALFONSO ALBA - LOCALIDAD SUBA | P1071: ALFONSO ALBA - LOCALIDAD SUBA | Q1071: DISTRIBUIDOR | R1071: =E1071/$E$2034 -> 7.492654e-05
A1072: 713 | B1072: 3757486 | C1072: 0 | D1072: FERRETERIA LUIS PENAGOS SAS | E1072: 3757486 | F1072: 713922.34 | G1072: 36984.8 | H1072: 0 | I1072: 0 | J1072: 36984.8 | K1072: 4434423.5 | L1072: 83003703900 | M1072: 830037039-8 | N1072: BOGOTA - BOGOTA | O1072: INDUSTRIAL | P1072: NORMA AGUILAR - LOCALIDAD MARTIRES | Q1072: DISTRIBUIDOR | R1072: =E1072/$E$2034 -> 7.4848834e-05
A1073: 488 | B1073: 3750744 | C1073: 0 | D1073: DIAZ PAREDES LUISA MARIA/ALMACEN DE PINTURAS D D & G | E1073: 3750744 | F1073: 712641.36 | G1073: 0 | H1073: 0 | I1073: 0 | J1073: 0 | K1073: 4463385.4 | L1073: 4170481100 | M1073: 41704811-7 | N1073: BOGOTA - BOGOTA | O1073: ALEJANDRO CARANTON -LOCALIDAD ANTONIO NARIÑO | P1073: ALEJANDRO CARANTON -LOCALIDAD ANTONIO NARIÑO | Q1073: DISTRIBUIDOR | R1073: =E1073/$E$2034 -> 7.4714534e-05
... A1362: 1808 | B1362: 1289030 | C1362: 0 | D1362: SANDOVAL CARDOZO JAIRO/FERRELECTRICOS J.S. 54 | E1362: 1289030 | F1362: 244915.7 | G1362: 0 | H1362: 0 | I1362: 0 | J1362: 0 | K1362: 1533945.7 | L1362: 1938253400 | M1362: 19382534-4 | N1362: BOGOTA - BOGOTA | O1362: DIANA ARENAS - LOCALIDAD CHAPINERO | P1362: DIANA ARENAS - LOCALIDAD CHAPINERO | Q1362: DISTRIBUIDOR | R1362: =E1362/$E$2034 -> 2.5677379e-05
A1363: 1456 | B1363: 1285234 | C1363: 0 | D1363: ORJUELA CAMPO MIGUEL | E1363: 1285234 | F1363: 244194.46 | G1363: 0 | H1363: 0 | I1363: 0 | J1363: 0 | K1363: 1529428.5 | L1363: 1718506500 | M1363: 17185065-4 | O1363: MOSTRADOR | P1363: MOSTRADOR | Q1363: PVP | R1363: =E1363/$E$2034 -> 2.5601763e-05
A1364: 963 | B1364: 1269882 | C1364: 0 | D1364: HELVER YESID GONZALEZ PUENTES | E1364: 1269882 | F1364: 241277.58 | G1364: 0 | H1364: 0 | I1364: 0 | J1364: 0 | K1364: 1511159.6 | L1364: 107372205500 | M1364: 1073722055-1 | N1364: BOGOTA - BOGOTA | O1364: TUL SAS | P1364: TUL SAS | Q1364: DISTRIBUIDOR | R1364: =E1364/$E$2034 -> 2.5295952e-05
A1365: 1424 | B1365: 1265228 | C1365: 0 | D1365: OBRACOL SAS CONSTRUCTORA | E1365: 1265228 | F1365: 240393.32 | G1365: 31630.7 | H1365: 0 | I1365: 0 | J1365: 31630.7 | K1365: 1473990.6 | L1365: 90039484800 | M1365: 900394848-3 | N1365: BOGOTA - BOGOTA | O1365: INSTITUCIONAL | P1365: INSTITUCIONAL | Q1365: INDUSTRIAL 2 | R1365: =E1365/$E$2034 -> 2.5203245e-05
A1366: 253 | B1366: 1259429 | C1366: 0 | D1366: CASTAÑEDA GRANADOS JUAN CARLOS / CONSORCIO FERRELECTRICOS | E1366: 1259429 | F1366: 239291.51 | G1366: 0 | H1366: 0 | I1366: 0 | J1366: 0 | K1366: 1498720.5 | L1366: 424575800 | M1366: 4245758-0 | N1366: BOGOTA - BOGOTA | O1366: ALFONSO ALBA - LOCALIDAD USAQUEN | P1366: ALFONSO ALBA - LOCALIDAD USAQUEN | Q1366: DISTRIBUIDOR | R1366: =E1366/$E$2034 -> 2.5087729e-05
A1367: 978 | B1367: 1234768 | C1367: 0 | D1367: HERNANDEZ PEÑA DIANA MARLEN / FERRELECTRICOS LA PALMITA DH | E1367: 1234768 | F1367: 234605.92 | G1367: 0 | H1367: 0 | I1367: 0 | J1367: 0 | K1367: 1469373.9 | L1367: 3519949600 | M1367: 35199496-1 | N1367: PACHO - CUNDINAMARCA | O1367: OMAR MONTAÑA - SABANA CENTRO | P1367: INACTIVO | Q1367: DISTRIBUIDOR | R1367: =E1367/$E$2034 -> 2.4596484e-05
A1368: 680 | B1368: 1227205 | C1368: 0 | D1368: FERRETERIA FM S.A.S. | E1368: 1227205 | F1368: 233168.95 | G1368: 0 | H1368: 0 | I1368: 0 | J1368: 0 | K1368: 1460373.9 | L1368: 90099463500 | M1368: 900994635-6 | N1368: BOGOTA - BOGOTA | O1368: ALFONSO ALBA - LOCALIDAD ENGATIVA | P1368: ALFONSO ALBA - LOCALIDAD ENGATIVA | Q1368: DISTRIBUIDOR | R1368: =E1368/$E$2034 -> 2.444583e-05
A1369: 1711 | B1369: 1217656 | C1369: 0 | D1369: RODRIGUEZ CASTRO JORGE ALVEIRO / FERREPINTURAS JR | E1369: 1217656 | F1369: 231354.64 | G1369: 0 | H1369: 0 | I1369: 0 | J1369: 0 | K1369: 1449010.6 | L1369: 409730900 | M1369: 4097309-1 | N1369: CHIQUINQUIRA - BOYACA | O1369: WILSON SEPULVEDA - BOYACA | P1369: WILSON SEPULVEDA - BOYACA | Q1369: DISTRIBUIDOR | R1369: =E1369/$E$2034 -> 2.4255615e-05
A1370: 1912 | B1370: 1216215 | C1370: 0 | D1370: THE OFICCE STORE SAS | E1370: 1216215 | F1370: 231080.85 | G1370: 0 | H1370: 0 | I1370: 0 | J1370: 0 | K1370: 1447295.9 | L1370: 90105541200 | M1370: 901055412-6 | N1370: BOGOTA - BOGOTA | O1370: DIANA ARENAS - LOCALIDAD BARRIOS UNIDOS | P1370: DIANA ARENAS - LOCALIDAD BARRIOS UNIDOS | Q1370: DISTRIBUIDOR | R1370: =E1370/$E$2034 -> 2.422691e-05
A1371: 647 | B1371: 1205363 | C1371: 0 | D1371: FERRELECTRICOS EL OASIS SAS | E1371: 1205363 | F1371: 229018.97 | G1371: 0 | H1371: 0 | I1371: 0 | J1371: 0 | K1371: 1434382 | L1371: 90169914300 | M1371: 901699143-3 | N1371: BOGOTA - BOGOTA | O1371: ALEJANDRO CARANTON -LOCALIDAD ANTONIO NARIÑO | P1371: ALEJANDRO CARANTON -LOCALIDAD ANTONIO NARIÑO | Q1371: DISTRIBUIDOR | R1371: =E1371/$E$2034 -> 2.4010739e-05
A1372: 158 | B1372: 1204596 | C1372: 0 | D1372: BENAVIDES BUITRAGO MARYOLY/FERRELECTRICOS LA 15 | E1372: 1204596 | F1372: 228873.24 | G1372: 0 | H1372: 0 | I1372: 0 | J1372: 0 | K1372: 1433469.2 | L1372: 5239619300 | M1372: 52396193-1 | N1372: MOSQUERA - CUNDINAMARCA | O1372: DIANA ARENAS - SABANA OCCIDENTE | P1372: DIANA ARENAS - SABANA OCCIDENTE | Q1372: DISTRIBUIDOR | R1372: =E1372/$E$2034 -> 2.399546e-05
A1373: 1667 | B1373: 1203795.2 | C1373: 0 | D1373: RETAMBORES BOGOTA S A S | E1373: 1203795.2 | F1373: 228721.1 | G1373: 0 | H1373: 0 | I1373: 0 | J1373: 0 | K1373: 1432516.3 | L1373: 90128924700 | M1373: 901289247-1 | N1373: SOACHA - CUNDINAMARCA | O1373: MOSTRADOR | P1373: MOSTRADOR | Q1373: PVP | R1373: =E1373/$E$2034 -> 2.3979509e-05
A1374: 952 | B1374: 1194242 | C1374: 0 | D1374: GUTIERREZ SAAVEDRA MAYERLLYS / PINTUELECTRICOS M Y M | E1374: 1194242 | F1374: 226905.98 | G1374: 0 | H1374: 0 | I1374: 0 | J1374: 0 | K1374: 1421148 | L1374: 102237509800 | M1374: 1022375098-1 | N1374: PAIPA - BOYACA | O1374: WILSON SEPULVEDA - BOYACA | P1374: WILSON SEPULVEDA - BOYACA | Q1374: DISTRIBUIDOR | R1374: =E1374/$E$2034 -> 2.3789209e-05
...

Sheet 2025
A1: # | B1: Valor Bruto | C1: Descuento | D1: Nombre de cliente/proveedor | E1: Subtotal | F1: Impuesto | G1: ReteFuente | H1: Rete IVA | I1: Rete ICA | J1: Total Reteciones | K1: Total Documento | L1: Cod SN | M1: NIT | N1: City | O1: Vendedor en doc | P1: Vendedor Actual | Q1: Canal de Cliente | R1: PARTICIPACION CLIENTE | S1: Columna1
A2: 1099 | B2: 3015219527 | C2: 1.2144983e+08 | D2: M SIERRA FERRETEROS S.A.S. "MONTEVIDEO" | E2: 2.8937697e+09 | F2: 5.4981624e+08 | G2: 71436972 | H2: 0 | I2: 0 | J2: 71436972 | K2: 3.372149e+09 | L2: 90134981300 | M2: 901349813-9 | N2: BOGOTA - BOGOTA | O2: GRANDES CUENTAS | P2: GRANDES CUENTAS | Q2: MAYORISTA INDUSTRIAL | R2: =E2/$E$1757 -> 0.050767493 | S2: =Tabla3[[#This Row],[Subtotal]]/12 -> 2.4114747e+08
A3: 275 | B3: 1843490842 | C3: 2339354.4 | D3: CENTRO PINTUCOLOR S.A.S. | E3: 1.8411515e+09 | F3: 3.4981878e+08 | G3: 45194876 | H3: 0 | I3: 0 | J3: 45194876 | K3: 2.1457754e+09 | L3: 90058246400 | M3: 900582464-5 | N3: BARRANCABERMEJA - SANTANDER | O3: EVELIO GARCIA - SANTANDER | P3: EVELIO GARCIA - SANTANDER | Q3: GRAN DISTRIBUIDOR | R3: =E3/$E$1757 -> 0.032300651 | S3: =Tabla3[[#This Row],[Subtotal]]/12 -> 1.5342929e+08
A4: 676 | B4: 1209088709 | C4: 0 | D4: FERRETERIA TUBOLAMINAS S A-CALI | E4: 1209088709 | F4: 2.2972685e+08 | G4: 29330074 | H4: 2884477.1 | I4: 0 | J4: 32214551 | K4: 1.406601e+09 | L4: 89032442001 | M4: 890324420-0 | N4: CALI - VALLE DEL CAUCA | O4: JORGE CASTRO - VALLE DE CAUCA | P4: JORGE CASTRO - VALLE DE CAUCA | Q4: GRAN DISTRIBUIDOR | R4: =E4/$E$1757 -> 0.021211917 | S4: =Tabla3[[#This Row],[Subtotal]]/12 -> 1.0075739e+08
A5: 554 | B5: 1090617249 | C5: 4447639.6 | D5: FEDUSE S.A.S | E5: 1.0861696e+09 | F5: 2.0637223e+08 | G5: 26672949 | H5: 0 | I5: 0 | J5: 26672949 | K5: 1.2658689e+09 | L5: 89130321200 | M5: 891303212-9 | N5: GUADALAJARA DE BUGA - VALLE DE | O5: JORGE CASTRO - VALLE DE CAUCA | P5: JORGE CASTRO - VALLE DE CAUCA | Q5: GRAN DISTRIBUIDOR | R5: =E5/$E$1757 -> 0.019055458 | S5: =Tabla3[[#This Row],[Subtotal]]/12 -> 90514134
A6: 1143 | B6: 1.0557465e+09 | C6: 2149094.9 | D6: MATERIALES SU CONSTRUCCION S.A. | E6: 1.0535974e+09 | F6: 2.0018351e+08 | G6: 25275756 | H6: 0 | I6: 0 | J6: 25275756 | K6: 1.2285052e+09 | L6: 80014765000 | M6: 800147650-1 | N6: MEDELLIN - ANTIOQUIA | O6: ANTIOQUIA | P6: ANTIOQUIA | Q6: MAYORISTA INDUSTRIAL | R6: =E6/$E$1757 -> 0.018484021 | S6: =Tabla3[[#This Row],[Subtotal]]/12 -> 87799784
A7: 945 | B7: 974667488 | C7: 5068830.2 | D7: INDURRUEDAS S A S "BMANGA" | E7: 9.6959866e+08 | F7: 1.8422374e+08 | G7: 23659010 | H7: 0 | I7: 0 | J7: 23659010 | K7: 1.1301634e+09 | L7: 89020795600 | M7: 890207956-5 | N7: BUCARAMANGA - SANTANDER | O7: EVELIO GARCIA - SANTANDER | P7: EVELIO GARCIA - SANTANDER | Q7: MAYORISTA INDUSTRIAL | R7: =E7/$E$1757 -> 0.01701037 | S7: =Tabla3[[#This Row],[Subtotal]]/12 -> 80799888
A8: 1120 | B8: 9.5826145e+08 | C8: 10098824 | D8: MARTILLO DISTRIBUIDOR MAYORISTA S.A.S. | E8: 9.4816263e+08 | F8: 1.801509e+08 | G8: 23606260 | H8: 0 | I8: 0 | J8: 23606260 | K8: 1.1047073e+09 | L8: 90144410400 | M8: 901444104-1 | N8: CALI - VALLE DEL CAUCA | O8: JORGE CASTRO - VALLE DE CAUCA | P8: JORGE CASTRO - VALLE DE CAUCA | Q8: MAYORISTA INDUSTRIAL | R8: =E8/$E$1757 -> 0.016634302 | S8: =Tabla3[[#This Row],[Subtotal]]/12 -> 79013553
A9: 929 | B9: 940692124 | C9: 0 | D9: HOLCIM COLOMBIA S.A | E9: 940692124 | F9: 1.787315e+08 | G9: 22942086 | H9: 26153978 | I9: 0 | J9: 49096065 | K9: 1.0703276e+09 | L9: 86000980800 | M9: 860009808-5 | N9: BOGOTA - BOGOTA | O9: GRANDES CUENTAS | P9: GRANDES CUENTAS | Q9: MAYORISTA INDUSTRIAL | R9: =E9/$E$1757 -> 0.016503242 | S9: =Tabla3[[#This Row],[Subtotal]]/12 -> 78391010
A10: 1098 | B10: 688456772 | C10: 26187382 | D10: M SIERRA FERRETEROS S.A.S "TIENDA BLER CENTRO" | E10: 6.6226939e+08 | F10: 1.2583118e+08 | G10: 16556735 | H10: 0 | I10: 0 | J10: 16556735 | K10: 7.7154384e+08 | L10: 90134981301 | M10: 901349813-9 | N10: BOGOTA - BOGOTA | O10: GRANDES CUENTAS | P10: GRANDES CUENTAS | Q10: MAYORISTA INDUSTRIAL | R10: =E10/$E$1757 -> 0.01161867 | S10: =Tabla3[[#This Row],[Subtotal]]/12 -> 55189116
A11: 1285 | B11: 604504509 | C11: 0 | D11: ORTIZ MURCIA AMPARO/FERROCED | E11: 604504509 | F11: 1.1485586e+08 | G11: 15082294 | H11: 0 | I11: 0 | J11: 15082294 | K11: 7.0427807e+08 | L11: 3617999600 | M11: 36179996-0 | N11: NEIVA - HUILA | O11: WILSON SEPULVEDA - HUILA - CAQUETA | P11: WILSON SEPULVEDA - HUILA - CAQUETA | Q11: GRAN DISTRIBUIDOR | R11: =E11/$E$1757 -> 0.010605259 | S11: =Tabla3[[#This Row],[Subtotal]]/12 -> 50375376
A12: 1599 | B12: 583451906 | C12: 9140364.8 | D12: SIDOC S.A.S. "YUMBO" | E12: 5.7431154e+08 | F12: 1.0911919e+08 | G12: 14066875 | H12: 13504130 | I12: 0 | J12: 27571004 | K12: 6.5585973e+08 | L12: 89033302300 | M12: 890333023-8 | N12: YUMBO - VALLE DEL CAUCA | O12: JORGE CASTRO - VALLE DE CAUCA | P12: JORGE CASTRO - VALLE DE CAUCA | Q12: GRAN DISTRIBUIDOR | R12: =E12/$E$1757 -> 0.010075562 | S12: =Tabla3[[#This Row],[Subtotal]]/12 -> 47859295
A13: 1601 | B13: 515763330 | C13: 8331660.5 | D13: SIDOC S.A.S." PEREIRA / DOSQUEBRADAS" | E13: 5.0743167e+08 | F13: 96412017 | G13: 12414922 | H13: 13120700 | I13: 0 | J13: 25535621 | K13: 5.7830807e+08 | L13: 89033302308 | M13: 890333023-8 | N13: DOS QUEBRADAS - RISARALDA | O13: JORGE CASTRO - EJE CAFETERO | P13: JORGE CASTRO - EJE CAFETERO | Q13: GRAN DISTRIBUIDOR | R13: =E13/$E$1757 -> 0.0089022404 | S13: =Tabla3[[#This Row],[Subtotal]]/12 -> 42285972
... A1269: 101 | B1269: 1917719 | C1269: 0 | D1269: ARENAS PEREZ MARTHA CECILIA/FERREDEPOSITO LA 74 | E1269: 1917719 | F1269: 364366.61 | G1269: 0 | H1269: 0 | I1269: 0 | J1269: 0 | K1269: 2282085.6 | L1269: 5179534300 | M1269: 51795343-8 | N1269: BOGOTA - BOGOTA | O1269: DIANA ARENAS - LOCALIDAD BARRIOS UNIDOS | P1269: DIANA ARENAS - LOCALIDAD BARRIOS UNIDOS | Q1269: DISTRIBUIDOR | R1269: =E1269/$E$1757 -> 3.364393e-05 | S1269: =Tabla3[[#This Row],[Subtotal]]/12 -> 159809.92
A1270: 1676 | B1270: 1917067 | C1270: 0 | D1270: TRANSPORTADORA MERCANTIL LTDA | E1270: 1917067 | F1270: 164138.91 | G1270: 0 | H1270: 0 | I1270: 0 | J1270: 0 | K1270: 2081205.9 | L1270: 83009959600 | M1270: 830099596-4 | O1270: TRANSPORTADORAS | P1270: TRANSPORTADORAS | Q1270: PVP | R1270: =E1270/$E$1757 -> 3.3632492e-05 | S1270: =Tabla3[[#This Row],[Subtotal]]/12 -> 159755.58
A1271: 242 | B1271: 1913652 | C1271: 0 | D1271: CASTRO GUTIERREZ NORBERTO/MAFERRO SERVICIOS DE ACERO NC | E1271: 1913652 | F1271: 363593.88 | G1271: 0 | H1271: 0 | I1271: 0 | J1271: 0 | K1271: 2277245.9 | L1271: 8044920000 | M1271: 80449200-6 | N1271: CHIA - CUNDINAMARCA | O1271: OMAR MONTAÑA - SABANA CENTRO | P1271: OMAR MONTAÑA - SABANA CENTRO | Q1271: DISTRIBUIDOR | R1271: =E1271/$E$1757 -> 3.357258e-05 | S1271: =Tabla3[[#This Row],[Subtotal]]/12 -> 159471
A1272: 1655 | B1272: 1913471 | C1272: 0 | D1272: TECNOHIERROS SAS | E1272: 1913471 | F1272: 361279.49 | G1272: 0 | H1272: 0 | I1272: 0 | J1272: 0 | K1272: 2274750.5 | L1272: 90143500200 | M1272: 901435002-0 | N1272: BOGOTA - BOGOTA | O1272: TUL SAS | P1272: TUL SAS | Q1272: DISTRIBUIDOR | R1272: =E1272/$E$1757 -> 3.3569404e-05 | S1272: =Tabla3[[#This Row],[Subtotal]]/12 -> 159455.92
A1273: 1754 | B1273: 1912969 | C1273: 0 | D1273: ZUÑIGA CARVAJAL ADRIANA DEL PILAR / OMEGA FERRETERIAS | E1273: 1912969 | F1273: 363464.11 | G1273: 0 | H1273: 0 | I1273: 0 | J1273: 0 | K1273: 2276433.1 | L1273: 101020400900 | M1273: 1010204009-1 | N1273: BOGOTA - BOGOTA | O1273: ALFONSO ALBA - LOCALIDAD ENGATIVA | P1273: ALFONSO ALBA - LOCALIDAD ENGATIVA | Q1273: DISTRIBUIDOR | R1273: =E1273/$E$1757 -> 3.3560597e-05 | S1273: =Tabla3[[#This Row],[Subtotal]]/12 -> 159414.08
A1274: 103 | B1274: 1908741 | C1274: 0 | D1274: ARFOS FERRETERIA LTDA | E1274: 1908741 | F1274: 362660.79 | G1274: 18627.75 | H1274: 0 | I1274: 0 | J1274: 18627.75 | K1274: 2252774 | L1274: 90021111200 | M1274: 900211112-7 | N1274: BOGOTA - BOGOTA | O1274: ALFONSO ALBA - LOCALIDAD ENGATIVA | P1274: ALFONSO ALBA - LOCALIDAD ENGATIVA | Q1274: DISTRIBUIDOR | R1274: =E1274/$E$1757 -> 3.3486423e-05 | S1274: =Tabla3[[#This Row],[Subtotal]]/12 -> 159061.75
A1275: 1714 | B1275: 1898492 | C1275: 0 | D1275: VASQUEZ MARIA ELISA/FERRETERIA J.I RODRIGUEZ | E1275: 1898492 | F1275: 360713.48 | G1275: 0 | H1275: 0 | I1275: 0 | J1275: 0 | K1275: 2259205.5 | L1275: 3977759000 | M1275: 39777590-0 | N1275: BOGOTA - BOGOTA | O1275: ALFONSO ALBA - LOCALIDAD SUBA | P1275: ALFONSO ALBA - LOCALIDAD SUBA | Q1275: DISTRIBUIDOR | R1275: =E1275/$E$1757 -> 3.3306617e-05 | S1275: =Tabla3[[#This Row],[Subtotal]]/12 -> 158207.67
A1276: 1055 | B1276: 1896550 | C1276: 0 | D1276: LAGUNA CAÑON HUGO JAVIER/TECNICOLOR | E1276: 1896550 | F1276: 360344.5 | G1276: 0 | H1276: 0 | I1276: 0 | J1276: 0 | K1276: 2256894.5 | L1276: 1731990400 | M1276: 17319904-6 | N1276: VILLAVICENCIO - META | O1276: WILSON SEPULVEDA - META | P1276: WILSON SEPULVEDA - META | Q1276: GRAN DISTRIBUIDOR | R1276: =E1276/$E$1757 -> 3.3272547e-05 | S1276: =Tabla3[[#This Row],[Subtotal]]/12 -> 158045.83
A1277: 1582 | B1277: 1891712 | C1277: 0 | D1277: SANTOS BARRERA MAURICIO ANIBAL/FERREDEPOSITO CONSTRUYA | E1277: 1891712 | F1277: 359425.28 | G1277: 0 | H1277: 0 | I1277: 0 | J1277: 0 | K1277: 2251137.3 | L1277: 568987100 | M1277: 5689871-4 | N1277: BOGOTA - BOGOTA | O1277: ALFONSO ALBA - LOCALIDAD USAQUEN | P1277: ALFONSO ALBA - LOCALIDAD USAQUEN | Q1277: DISTRIBUIDOR | R1277: =E1277/$E$1757 -> 3.3187671e-05 | S1277: =Tabla3[[#This Row],[Subtotal]]/12 -> 157642.67
A1278: 854 | B1278: 1868310 | C1278: 0 | D1278: GUERRERO SANCHEZ HECTOR EMANUEL / MULTICOLORES GS | E1278: 1868310 | F1278: 354978.9 | G1278: 0 | H1278: 0 | I1278: 0 | J1278: 0 | K1278: 2223288.9 | L1278: 100004843800 | M1278: 1000048438-0 | N1278: BOGOTA - BOGOTA | O1278: ALFONSO ALBA - LOCALIDAD USAQUEN | P1278: ALFONSO ALBA - LOCALIDAD USAQUEN | Q1278: DISTRIBUIDOR | R1278: =E1278/$E$1757 -> 3.2777112e-05 | S1278: =Tabla3[[#This Row],[Subtotal]]/12 -> 155692.5
A1279: 46 | B1279: 1859752 | C1279: 0 | D1279: AGUILAR VASQUEZ MARTHA LUCIA/FERRETEJAS Y MANGUERAS | E1279: 1859752 | F1279: 353352.88 | G1279: 0 | H1279: 0 | I1279: 0 | J1279: 0 | K1279: 2213104.9 | L1279: 3541059100 | M1279: 35410591-8 | N1279: ZIPAQUIRA - CUNDINAMARCA | O1279: OMAR MONTAÑA - SABANA CENTRO | P1279: OMAR MONTAÑA - SABANA CENTRO | Q1279: DISTRIBUIDOR | R1279: =E1279/$E$1757 -> 3.2626973e-05 | S1279: =Tabla3[[#This Row],[Subtotal]]/12 -> 154979.33
A1280: 1083 | B1280: 1856876 | C1280: 0 | D1280: LOPEZ RODRIGUEZ ADRIANA MARCELA | E1280: 1856876 | F1280: 352806.44 | G1280: 0 | H1280: 0 | I1280: 0 | J1280: 0 | K1280: 2209682.4 | L1280: 4362785300 | M1280: 43627853 | N1280: MOSQUERA - CUNDINAMARCA | O1280: EMPLEADO | P1280: EMPLEADO | Q1280: INDUSTRIAL 2 | R1280: =E1280/$E$1757 -> 3.2576517e-05 | S1280: =Tabla3[[#This Row],[Subtotal]]/12 -> 154739.67
A1281: 1114 | B1281: 1856802 | C1281: 0 | D1281: MARIO RODRIGUEZ GUTIERREZ | E1281: 1856802 | F1281: 352792.38 | G1281: 0 | H1281: 0 | I1281: 0 | J1281: 0 | K1281: 2209594.4 | L1281: 7923020500 | M1281: 79230205 | N1281: BOGOTA - BOGOTA | O1281: ALFONSO ALBA - LOCALIDAD SUBA | P1281: ALFONSO ALBA - LOCALIDAD SUBA | Q1281: DISTRIBUIDOR | R1281: =E1281/$E$1757 -> 3.2575219e-05 | S1281: =Tabla3[[#This Row],[Subtotal]]/12 -> 154733.5
A1282: 245 | B1282: 1850724 | C1282: 0 | D1282: CASTRO LOPEZ DIEGO JAVIER/ ESTRUCTURAS METALICAS DEL CAUCA | E1282: 1850724 | F1282: 351637.56 | G1282: 46268.1 | H1282: 0 | I1282: 0 | J1282: 46268.1 | K1282: 2156093.5 | L1282: 1054755800 | M1282: 10547558-2 | N1282: POPAYAN - CAUCA | O1282: JORGE CASTRO - CAUCA | P1282: JORGE CASTRO - CAUCA | Q1282: DISTRIBUIDOR | R1282: =E1282/$E$1757 -> 3.2468588e-05 | S1282: =Tabla3[[#This Row],[Subtotal]]/12 -> 154227
... A1565: 1122 | B1565: 427392 | C1565: 0 | D1565: MARTIN BARRETO CAMPO ELIAS/MULTICOLOR CAMPOS | E1565: 427392 | F1565: 81204.48 | G1565: 0 | H1565: 0 | I1565: 0 | J1565: 0 | K1565: 508596.48 | L1565: 7956394300 | M1565: 79563943-3 | N1565: SOACHA - CUNDINAMARCA | O1565: ALEJANDRO CARANTON -SOACHA - SIBATE | P1565: ALEJANDRO CARANTON -SOACHA - SIBATE | Q1565: DISTRIBUIDOR | R1565: =E1565/$E$1757 -> 7.4980467e-06 | S1565: =Tabla3[[#This Row],[Subtotal]]/12 -> 35616
A1566: 1305 | B1566: 420412 | C1566: 0 | D1566: PAEZ QUITO FABIO GUILLERMO | E1566: 420412 | F1566: 79878.28 | G1566: 0 | H1566: 0 | I1566: 0 | J1566: 0 | K1566: 500290.28 | L1566: 8017211900 | M1566: 80172119 | O1566: EMPLEADO | P1566: EMPLEADO | Q1566: INDUSTRIAL 2 | R1566: =E1566/$E$1757 -> 7.3755915e-06 | S1566: =Tabla3[[#This Row],[Subtotal]]/12 -> 35034.333
A1567: 1180 | B1567: 416737 | C1567: 0 | D1567: MONTAÑEZ SILVA EDISON YAMID / FERRELECTRICOS MONTAÑEZ | E1567: 416737 | F1567: 79180.03 | G1567: 0 | H1567: 0 | I1567: 0 | J1567: 0 | K1567: 495917.03 | L1567: 101902499800 | M1567: 1019024998-9 | N1567: BOGOTA - BOGOTA | O1567: TUL SAS | P1567: TUL SAS | Q1567: DISTRIBUIDOR | R1567: =E1567/$E$1757 -> 7.3111183e-06 | S1567: =Tabla3[[#This Row],[Subtotal]]/12 -> 34728.083
A1568: 63 | B1568: 415986 | C1568: 0 | D1568: ALEMAN VILLAMIZAR DIEGO ANDRES | E1568: 415986 | F1568: 79037.34 | G1568: 0 | H1568: 0 | I1568: 0 | J1568: 0 | K1568: 495023.34 | L1568: 103164554300 | M1568: 1031645543 | N1568: BOGOTA - BOGOTA | O1568: EMPLEADO | P1568: EMPLEADO | Q1568: INDUSTRIAL 2 | R1568: =E1568/$E$1757 -> 7.297943e-06 | S1568: =Tabla3[[#This Row],[Subtotal]]/12 -> 34665.5
A1569: 1749 | B1569: 411537 | C1569: 0 | D1569: ZUBIETA VEGA OSWALDO / FERRESUMINISTRO E INSUMOS DE LA SABANA | E1569: 411537 | F1569: 78192.03 | G1569: 0 | H1569: 0 | I1569: 0 | J1569: 0 | K1569: 489729.03 | L1569: 1134945900 | M1569: 11349459-6 | N1569: ZIPAQUIRA - CUNDINAMARCA | O1569: OMAR MONTAÑA - SABANA CENTRO | P1569: OMAR MONTAÑA - SABANA CENTRO | Q1569: DISTRIBUIDOR | R1569: =E1569/$E$1757 -> 7.219891e-06 | S1569: =Tabla3[[#This Row],[Subtotal]]/12 -> 34294.75
A1570: 1151 | B1570: 411460 | C1570: 0 | D1570: MEJIA SUAREZ CLARA INES | E1570: 411460 | F1570: 78177.4 | G1570: 0 | H1570: 0 | I1570: 0 | J1570: 0 | K1570: 489637.4 | L1570: 5196653600 | M1570: 51966536 | N1570: BOGOTA - BOGOTA | O1570: EMPLEADO | P1570: EMPLEADO | Q1570: INDUSTRIAL 2 | R1570: =E1570/$E$1757 -> 7.2185401e-06 | S1570: =Tabla3[[#This Row],[Subtotal]]/12 -> 34288.333
A1571: 1695 | B1571: 411201 | C1571: 0 | D1571: URBANCAR SAS | E1571: 411201 | F1571: 78128.19 | G1571: 0 | H1571: 0 | I1571: 0 | J1571: 0 | K1571: 489329.19 | L1571: 90088400000 | M1571: 900884000-8 | N1571: MADRID - CUNDINAMARCA | O1571: DIANA ARENAS - SABANA OCCIDENTE | P1571: DIANA ARENAS - SABANA OCCIDENTE | Q1571: DISTRIBUIDOR | R1571: =E1571/$E$1757 -> 7.2139963e-06 | S1571: =Tabla3[[#This Row],[Subtotal]]/12 -> 34266.75
A1572: 1513 | B1572: 404324 | C1572: 0 | D1572: RODRIGUEZ VASQUEZ OMAR ARMANDO/FERRELECTRICOS RG | E1572: 404324 | F1572: 76821.56 | G1572: 0 | H1572: 0 | I1572: 0 | J1572: 0 | K1572: 481145.56 | L1572: 1943226900 | M1572: 19432269-7 | N1572: EL COLEGIO - CUNDINAMARCA | O1572: OMAR MONTAÑA -SUR TOLIMA | P1572: OMAR MONTAÑA -SUR TOLIMA | Q1572: DISTRIBUIDOR | R1572: =E1572/$E$1757 -> 7.0933481e-06 | S1572: =Tabla3[[#This Row],[Subtotal]]/12 -> 33693.667
A1573: 1135 | B1573: 389754 | C1573: 0 | D1573: MATALLANA CUERVO FLOR ALBA/DEPOSITO DE MATERIALES EL CEDRO | E1573: 389754 | F1573: 74053.26 | G1573: 0 | H1573: 0 | I1573: 0 | J1573: 0 | K1573: 463807.26 | L1573: 3980886200 | M1573: 39808862-3 | N1573: TABIO - CUNDINAMARCA | O1573: OMAR MONTAÑA - SABANA CENTRO | P1573: OMAR MONTAÑA - SABANA CENTRO | Q1573: DISTRIBUIDOR | R1573: =E1573/$E$1757 -> 6.8377361e-06 | S1573: =Tabla3[[#This Row],[Subtotal]]/12 -> 32479.5
A1574: 1068 | B1574: 387504 | C1574: 0 | D1574: LEON CASTAÑEDA CARLOS ANDRES / FERRELECTRICOS C Y C 2 | E1574: 387504 | F1574: 73625.76 | G1574: 0 | H1574: 0 | I1574: 0 | J1574: 0 | K1574: 461129.76 | L1574: 101429982200 | M1574: 1014299822-3 | N1574: BOGOTA - BOGOTA | O1574: ALFONSO ALBA - LOCALIDAD ENGATIVA | P1574: ALFONSO ALBA - LOCALIDAD ENGATIVA | Q1574: DISTRIBUIDOR | R1574: =E1574/$E$1757 -> 6.7982627e-06 | S1574: =Tabla3[[#This Row],[Subtotal]]/12 -> 32292
A1575: 1132 | B1575: 381447 | C1575: 0 | D1575: MARTINEZ PRIETO MARTHA DIVIA / PAPELERIA Y CAFÉ INTERNET LA UNIVERSAL | E1575: 381447 | F1575: 72474.93 | G1575: 0 | H1575: 0 | I1575: 0 | J1575: 0 | K1575: 453921.93 | L1575: 2063433100 | M1575: 20634331-7 | N1575: GUADUAS - CUNDINAMARCA | O1575: OMAR MONTAÑA - NTE DEL TOLIMA | P1575: OMAR MONTAÑA - NTE DEL TOLIMA | Q1575: DISTRIBUIDOR | R1575: =E1575/$E$1757 -> 6.6920004e-06 | S1575: =Tabla3[[#This Row],[Subtotal]]/12 -> 31787.25
A1576: 47 | B1576: 380252.1 | C1576: 0 | D1576: AIDA JANETH GAMEZ VILLARRAGA | E1576: 380252.1 | F1576: 72247.9 | G1576: 0 | H1576: 0 | I1576: 0 | J1576: 0 | K1576: 452500 | L1576: 5156827300 | M1576: 51568273 | N1576: BOGOTA - BOGOTA | O1576: E - COMMERCE | P1576: E - COMMERCE | Q1576: PVP | R1576: =E1576/$E$1757 -> 6.6710374e-06 | S1576: =Tabla3[[#This Row],[Subtotal]]/12 -> 31687.675
A1577: 1200 | B1577: 375110 | C1577: 0 | D1577: MORENO JIMENEZ JOSE SEIR/FERRETERIA EL AMIGASO | E1577: 375110 | F1577: 71270.9 | G1577: 0 | H1577: 0 | I1577: 0 | J1577: 0 | K1577: 446380.9 | L1577: 7983989200 | M1577: 79839892-2 | N1577: BOGOTA - BOGOTA | O1577: ALEJANDRO CARANTON -LOCALIDAD KENNEDY | P1577: ALEJANDRO CARANTON -LOCALIDAD KENNEDY | Q1577: DISTRIBUIDOR | R1577: =E1577/$E$1757 -> 6.5808258e-06 | S1577: =Tabla3[[#This Row],[Subtotal]]/12 -> 31259.167
...

Sheet Detalle Vendedores
B2: PARTICIPACIÓN GENERAL | F2: CRECIMIENTO VS 2024 | L2: CRECIMIENTO DETALLADO X ZONA VS 2024
B3: Asesor Comercial | C3: Participacion % | D3: Participacion $ (MM) | F3: Asesor Comercial | G3: VENTAS 2024 | H3: VENTAS 2025 | I3: CRECIMIENTO | L3: Asesor Comercial | M3: Zona | N3: VENTAS 2024 | O3: VENTAS 2025 | P3: CRECIMIENTO | Q3: PARTICIPACIÓN ZONA 2025
B4: Jorge Castro | C4: 0.2425 | D4: 13823 | F4: Jorge Castro | G4: 11489023266 | H4: 13823417353 | I4: =(H4-G4)/H4 -> 0.16887243 | K4: ASESORES VIAJEROS | L4: Jorge Castro | M4: Valle Del Cauca | N4: 6927872874 | O4: 7558893415 | P4: =(O4-N4)/O4 -> 0.083480545 | Q4: =O4/'2025'!$E$1757 -> 0.13261113 | R4: =SUM(Q4:Q8) -> 0.24233774
B5: Grandes Cuentas | C5: 0.138 | D5: 7866 | F5: Grandes Cuentas | G5: 7367703218 | H5: 8238296111 | I5: =(H5-G5)/H5 -> 0.10567633 | M5: Eje Cafetero | N5: 2018866302 | O5: 2816248608 | P5: =(O5-N5)/O5 -> 0.28313633 | Q5: =O5/'2025'!$E$1757 -> 0.049407484
B6: Omar Montaña | C6: 0.1354 | D6: 7718 | F6: Omar Montaña | G6: 7056073629 | H6: 7718923702 | I6: =(H6-G6)/H6 -> 0.085873381 | M6: Cauca | N6: 1748089511 | O6: 2246645092 | P6: =(O6-N6)/O6 -> 0.22191114 | Q6: =O6/'2025'!$E$1757 -> 0.039414518
B7: Wilson Sepulveda | C7: 0.12 | D7: 6841 | F7: Wilson Sepulveda | G7: 5468134228 | H7: 6841728666 | I7: =(H7-G7)/H7 -> 0.20076716 | M7: Nariño | N7: 733534298 | O7: 1101381379 | P7: =(O7-N7)/O7 -> 0.33398702 | Q7: =O7/'2025'!$E$1757 -> 0.019322329
B8: Evelio Garcia | C8: 0.1026 | D8: 5847 | F8: Evelio Garcia | G8: 5584181528 | H8: 5847496154 | I8: =(H8-G8)/H8 -> 0.045030321 | M8: Putumayo | N8: 60669280 | O8: 90190834 | P8: =(O8-N8)/O8 -> 0.32732322 | Q8: =O8/'2025'!$E$1757 -> 0.001582283
B9: Antioquia | C9: 0.0479 | D9: 2732 | F9: Antioquia | G9: 2544954537 | H9: 2732456699 | I9: =(H9-G9)/H9 -> 0.06862036 | L9: Omar Montaña | M9: Tolima Sur | N9: 2936016665 | O9: 3327966394 | P9: =(O9-N9)/O11 -> 0.35945675 | Q9: =O9/'2025'!$E$1757 -> 0.058384919 | R9: =SUM(Q9:Q11) -> 0.13541866
B10: Institucional/Industrial | C10: 0.0449 | D10: 2558 | F10: Institucional/Industrial | G10: 2423357672 | H10: 2558604467 | I10: =(H10-G10)/H10 -> 0.052859595 | M10: Sabana Centro | N10: 3128272264 | O10: 3300562610 | P10: =(O10-N10)/O9 -> 0.051770458 | Q10: =O10/'2025'!$E$1757 -> 0.057904155
B11: Norma Aguilar | C11: 0.0398 | D11: 2269 | F11: Norma Aguilar | G11: 2123335456 | H11: 2269767081 | I11: =(H11-G11)/H11 -> 0.064513943 | M11: Tolima Norte | N11: 991774699 | O11: 1090394698 | P11: =(O11-N11)/O10 -> 0.029879754 | Q11: =O11/'2025'!$E$1757 -> 0.019129582
B12: Cristian Betancourt | C12: 0.0316 | D12: 1801 | F12: Cristian Betancourt | G12: 1101238952 | H12: 1429925803 | I12: =(H12-G12)/H12 -> 0.22986287 | L12: Wilson Sepulveda | M12: Huila-Caqueta | N12: 2914498252 | O12: 3803245626 | P12: =(O12-N12)/O12 -> 0.2336813 | Q12: =O12/'2025'!$E$1757 -> 0.066723086 | R12: =SUM(Q12:Q16) -> 0.12002939
B13: Diana Arenas | C13: 0.0296 | D13: 1687 | F13: Diana Arenas | G13: 1476650679 | H13: 1687814401 | I13: =(H13-G13)/H13 -> 0.12511075 | M13: Meta | N13: 1157826909 | O13: 1342010763 | P13: =(O13-N13)/O13 -> 0.13724469 | Q13: =O13/'2025'!$E$1757 -> 0.023543865
B14: Alfonso Alba | C14: 0.0271 | D14: 1545 | F14: Alfonso Alba | G14: 1587407347 | H14: 1545341238 | I14: =(H14-G14)/H14 -> -0.027221243 | M14: Boyaca | N14: 867458814 | O14: 1055139783 | P14: =(O14-N14)/O14 -> 0.17787309 | Q14: =O14/'2025'!$E$1757 -> 0.01851108
B15: Alejandro Caranton | C15: 0.0179 | D15: 1022 | F15: Alejandro Caranton | G15: 952099324 | H15: 1022425687 | I15: =(H15-G15)/H15 -> 0.068783838 | M15: Guaviare | N15: 326326498 | O15: 370177128 | P15: =(O15-N15)/O15 -> 0.11845851 | Q15: =O15/'2025'!$E$1757 -> 0.0064942848
B16: TOTAL | C16: =SUM(C4:C15) -> 0.9773 | D16: =SUM(D4:D15) -> 55709 | F16: TOTAL | G16: =SUM(G4:G15) -> 49174159836 | H16: =SUM(H4:H15) -> 55716197362 | M16: Casanare | N16: 202023754 | O16: 271155366 | P16: =(O16-N16)/O16 -> 0.25495203 | Q16: =O16/'2025'!$E$1757 -> 0.0047570745
L17: Evelio Garcia | M17: Santander | N17: 4248642582 | O17: 4388642074 | P17: =(O17-N17)/O17 -> 0.031900412 | Q17: =O17/'2025'!$E$1757 -> 0.076993119 | R17: =SUM(Q17:Q21) -> 0.10258685
M18: Norte del Santander | N18: 864987728 | O18: 892894634 | P18: =(O18-N18)/O18 -> 0.031254422 | Q18: =O18/'2025'!$E$1757 -> 0.015664696
M19: Cesar | N19: 342602428 | O19: 450234194 | P19: =(O19-N19)/O19 -> 0.23905729 | Q19: =O19/'2025'!$E$1757 -> 0.0078987838
M20: Santander 2 | N20: 109771657 | O20: 103293534 | P20: =(O20-N20)/O20 -> -0.062715668 | Q20: =O20/'2025'!$E$1757 -> 0.0018121531
B21: CRECIMIENTO CLIENTES VS 2024 | M21: Arauca | N21: 18177132 | O21: 12431718 | P21: =(O21-N21)/O21 -> -0.46215768 | Q21: =O21/'2025'!$E$1757 -> 0.00021809861
B22: CLIENTE | C22: CASTILLO MATEUS ALFRED NEY/NEY PINTURAS | L22: Cristian Betancourt | M22: Costa Norte | N22: 556794398 | O22: 689396605 | P22: =(O22-N22)/O22 -> 0.19234531 | Q22: =O22/'2025'!$E$1757 -> 0.012094583 | R22: =SUM(Q22:Q24) -> 0.025086222
B23: VENTAS 2024 | C23: =VLOOKUP(C22,'2024'!D1:E2033,2,FALSE) -> 30146177 | M23: Costa Centro | N23: 378092078 | O23: 479462732 | P23: =(O23-N23)/O23 -> 0.21142551 | Q23: =O23/'2025'!$E$1757 -> 0.0084115612
B24: VENTAS 2025 | C24: =VLOOKUP(C22,'2025'!D2:E2034,2,FALSE) -> 10466798 | M24: Costa Sur | N24: 166352476 | O24: 261066466 | P24: =(O24-N24)/O24 -> 0.36279646 | Q24: =O24/'2025'!$E$1757 -> 0.0045800777
B25: CRECIMIENTO | C25: =(C24-C23)/C24 -> -1.8801718 | K25: ASESORTES BOGOTA | L25: Norma Aguilar | M25: Ciudad Bolivar | N25: 93310279 | O25: 90018093 | P25: =(O25-N25)/O25 -> -0.036572492 | Q25: =O25/'2025'!$E$1757 -> 0.0015792525 | R25: =SUM(Q25:Q31) -> 0.039820164
M26: Candelaria | N26: 34960963 | O26: 35709766 | P26: =(O26-N26)/O26 -> 0.020969138 | Q26: =O26/'2025'!$E$1757 -> 0.00062648223
M27: Martires | N27: 1141683970 | O27: 1282647094 | P27: =(O27-N27)/O27 -> 0.10990016 | Q27: =O27/'2025'!$E$1757 -> 0.022502405
M28: Puente Aranda | N28: 386935898 | O28: 335985167 | P28: =(O28-N28)/O28 -> -0.15164577 | Q28: =O28/'2025'!$E$1757 -> 0.0058944306
M29: San Cristobal | N29: 124839552 | O29: 146275291 | P29: =(O29-N29)/O29 -> 0.14654381 | Q29: =O29/'2025'!$E$1757 -> 0.0025662131
M30: Santafe | N30: 160721572 | O30: 165918418 | P30: =(O30-N30)/O30 -> 0.031321694 | Q30: =O30/'2025'!$E$1757 -> 0.0029108267
M31: Usme | N31: 177883222 | O31: 213213252 | P31: =(O31-N31)/O31 -> 0.16570279 | Q31: =O31/'2025'!$E$1757 -> 0.0037405541
L32: Diana Arenas | M32: Barrios Unidos | N32: 823520526 | O32: 872573530 | P32: =(O32-N32)/O32 -> 0.05621647 | Q32: =O32/'2025'!$E$1757 -> 0.015308188 | R32: =SUM(Q32:Q36) -> 0.029610548
M33: Chapinero | N33: 76148423 | O33: 142651404 | P33: =(O33-N33)/O33 -> 0.46619226 | Q33: =O33/'2025'!$E$1757 -> 0.0025026367
M34: Fontibon | N34: 154808223 | O34: 145783896 | P34: =(O34-N34)/O34 -> -0.061902084 | Q34: =O34/'2025'!$E$1757 -> 0.0025575922
M35: Teusaquillo | N35: 46668269 | O35: 39177746 | P35: =(O35-N35)/O35 -> -0.19119331 | Q35: =O35/'2025'!$E$1757 -> 0.00068732351
M36: Sabana Occidente | N36: 375505249 | O36: 487627825 | P36: =(O36-N36)/O36 -> 0.22993474 | Q36: =O36/'2025'!$E$1757 -> 0.0085548073
L37: Alfonso Alba | M37: Suba | N37: 895985135 | O37: 846450739 | P37: =(O37-N37)/O37 -> -0.058520117 | Q37: =O37/'2025'!$E$1757 -> 0.014849897 | R37: =SUM(Q37:Q39) -> 0.027111038
M38: Engativa | N38: 433051305 | O38: 456230961 | P38: =(O38-N38)/O38 -> 0.050806846 | Q38: =O38/'2025'!$E$1757 -> 0.0080039894
M39: Usaquen | N39: 258370907 | O39: 242659538 | P39: =(O39-N39)/O39 -> -0.064746554 | Q39: =O39/'2025'!$E$1757 -> 0.0042571516
L40: Alejandro Caranton | M40: Antonio Nariño | N40: 62567596 | O40: 63810617 | P40: =(O40-N40)/O40 -> 0.019479846 | Q40: =O40/'2025'!$E$1757 -> 0.0011194758 | R40: =SUM(Q40:Q45) -> 0.017937205
M41: Bosa | N41: 175565667 | O41: 240169438 | P41: =(O41-N41)/O41 -> 0.26899247 | Q41: =O41/'2025'!$E$1757 -> 0.004213466
...
